Exception on /get_location [GET]
Traceback (most recent call last):
  File "C:\Users\danib\PycharmProjects\flaskProject\.venv\Lib\site-packages\flask\app.py", line 1473, in wsgi_app
    response = self.full_dispatch_request()
               ^^^^^^^^^^^^^^^^^^^^^^^^^^^^
  File "C:\Users\danib\PycharmProjects\flaskProject\.venv\Lib\site-packages\flask\app.py", line 882, in full_dispatch_request
    rv = self.handle_user_exception(e)
         ^^^^^^^^^^^^^^^^^^^^^^^^^^^^^
  File "C:\Users\danib\PycharmProjects\flaskProject\.venv\Lib\site-packages\flask_cors\extension.py", line 194, in wrapped_function
    return cors_after_request(app.make_response(f(*args, **kwargs)))
                                                ^^^^^^^^^^^^^^^^^^
  File "C:\Users\danib\PycharmProjects\flaskProject\.venv\Lib\site-packages\flask\app.py", line 880, in full_dispatch_request
    rv = self.dispatch_request()
         ^^^^^^^^^^^^^^^^^^^^^^^
  File "C:\Users\danib\PycharmProjects\flaskProject\.venv\Lib\site-packages\flask\app.py", line 865, in dispatch_request
    return self.ensure_sync(self.view_functions[rule.endpoint])(**view_args)  # type: ignore[no-any-return]
           ^^^^^^^^^^^^^^^^^^^^^^^^^^^^^^^^^^^^^^^^^^^^^^^^^^^^^^^^^^^^^^^^^
  File "C:\Users\danib\OneDrive\Documents\Weather_project\flaskProject\weather_module.py", line 120, in get_location
    utc_offset = timezone_data['rawOffset'] + timezone_data['dstOffset']
                 ~~~~~~~~~~~~~^^^^^^^^^^^^^
KeyError: 'rawOffset'
